Workbook
Name Comprar: [1]Param!#REF!
Name início_da_tarefa: [2]CronogramaDeProjeto!$E1
Name Início_do_projeto: '[5]Gráfico de Gantt'!$G$5
Name Início_do_projeto: 'Gráfico de Gantt'!$G$5
Name Periodicidade: [3]Param!$AB$5:$AB$9
Name progresso_da_tarefa: [2]CronogramaDeProjeto!$D1
Name Semana_de_exibição: '[5]Gráfico de Gantt'!$G$6
Name Semana_de_exibição: 'Gráfico de Gantt'!$G$6
Name Status: [1]Param!#REF!
Name término_da_tarefa: [2]CronogramaDeProjeto!$F1
Name VersaoExcel: [3]Param!$D$15:$E$15
Name VersaoSR: [3]Param!$C$24:$C$26

Sheet Project Charter (2)

Sheet Diagrama de rede-precedência
A8: Etapas – Atividades - | B8: Data Início | C8: Data Fim | D8: Duração em DIAS
A9: Iniciação e Planejamento
A10: Definição de objetivos, escopo e requisitos do projeto | B10: 45870 | C10: =B10+D10 -> 45872 | D10: 2
A11: Reunião com patrocinadores e identificação de stakeholders e usuários | B11: =C10+D10 -> 45874 | C11: =B11+D11 -> 45875 | D11: 1
A12: Formação da equipe e definição de papéis | B12: =C11+D11 -> 45876 | C12: =B12+D12 -> 45879 | D12: 3
A13: Escolha de tecnologias, ferramentas e arquitetura do sistema | B13: =C12+D12 -> 45882 | C13: =B13+D13 -> 45883 | D13: 1
A14: Estruturação do cronograma, WBS, marcos e análise de riscos | B14: =C13+D13 -> 45884 | C14: =B14+D14 -> 45889 | D14: 5
A15: Design e Prototipagem
A16: Criação do design UI/UX e definição dos fluxos de navegação | B16: =C14 -> 45889 | C16: =B16+D16 -> 45893 | D16: 4 | I16: PDI -Primeiro dia de início | L16: UDI - Último dia de início
A17: Desenvolvimento de protótipos visuais e validação com stakeholders | B17: =C16 -> 45893 | C17: =B17+D17 -> 45900 | D17: 7 | I17: PDT - Primeito dia de término | L17: UDT - Último dia de término
A18: Ajustes e refinamentos baseados em feedbacks | B18: =C17 -> 45900 | C18: =B18+D18 -> 45911 | D18: 11 | I18: FL-Folgas Livres | L18: 0 | M18: É o caminho crítico
A19: Desenvolvimento e Integração | I19: FT-Folgas totais
A20: Modelagem de dados e implementação de banco de dados | B20: =C18 -> 45911 | C20: =B20+D20 -> 45918 | D20: 7
A21: Desenvolvimento do back-end, front-end e APIs | B21: =C20 -> 45918 | C21: =B21+D21 -> 45924 | D21: 6 | H21: modelo
A22: Criação do dashboard (gráficos, métricas e relatórios) | B22: =C21 -> 45924 | C22: =B22+D22 -> 45927 | D22: 3 | H22: atividade | I22: duração | V22: Desenvolvimento do back-end, front-end e APIs
A23: Integração com sistemas externos e simulação de dados | B23: =C22 -> 45927 | C23: =B23+D23 -> 45933 | D23: 6 | H23: PDI | I23: PDT | K23: Reunião com patrocinadores e identificação de stakeholders e usuários | O23: Criação do design UI/UX e definição dos fluxos de navegação | V23: 6
A24: Implementação de funcionalidades inteligentes (IA, alertas e exportações) | B24: =C23 -> 45933 | C24: =B24+D24 -> 45938 | D24: 5 | H24: UDI | I24: UDT | K24: 1 | O24: 4 | V24: 45918 | W24: 2
A25: Testes e Validação | H25: FL | I25: FT | K25: 45874 | L25: 2 | O25: 45889 | P25: 2 | V25: 45924 | W25: 0
A26: Testes de funcionalidade, desempenho, segurança e responsividade | B26: =C24 -> 45938 | C26: =B26+D26 -> 45943 | D26: 5 | K26: 45875 | L26: 0 | O26: 45893 | P26: 0 | V26: 6 | W26: -2
A27: Correção de bugs e ajustes finais antes do lançamento | B27: =C26 -> 45943 | C27: =B27+D27 -> 45946 | D27: 3 | K27: 1 | L27: -2 | O27: 4 | P27: -2
A28: Lançamento e Pós-Lançamento | H28: Definição dos objetivos do projeto | AU28: Treinamento da equipe e apresentação ao público
A29: Documentação técnica e deploy do sistema | B29: =C27 -> 45946 | C29: =B29+D29 -> 45950 | D29: 4 | H29: 2 | K29: Formação da equipe e definição de papéis | O29: Desenvolvimento de protótipos visuais e validação com stakeholders | S29: Modelagem de dados e implementação de banco de dados | V29: Criação do dashboard (gráficos, métricas e relatórios) | AU29: 4
A30: Monitoramento de métricas e coleta de feedbacks | B30: =C29 -> 45950 | C30: =B30+D30 -> 45954 | D30: 4 | H30: 45870 | I30: 2 | K30: 3 | O30: 7 | S30: 7 | V30: 3 | Z30: Testes de funcionalidade, desempenho, segurança e responsividade | AU30: 45964 | AV30: 2
A31: Atualizações e melhorias contínuas | B31: =C30 -> 45954 | C31: =B31+D31 -> 45959 | D31: 5 | H31: 45872 | I31: 0 | K31: 45876 | L31: 2 | O31: 45893 | P31: 2 | S31: 45911 | T31: 2 | V31: 45924 | W31: 2 | Z31: 5 | AD31: Correção de bugs e ajustes finais antes do lançamento | AH31: Documentação técnica e deploy do sistema | AL31: Monitoramento de métricas e coleta de feedbacks | AQ31: Criação de materiais de divulgação e campanhas em mídias sociais | AU31: 45968 | AV31: 0
A32: Divulgação e Expansão | H32: 2 | I32: -2 | K32: 45879 | L32: 0 | O32: 45900 | P32: 0 | S32: 45918 | T32: 0 | V32: 45927 | W32: 0 | Z32: 45938 | AA32: 2 | AD32: 3 | AH32: 4 | AL32: 4 | AQ32: 5 | AU32: 4 | AV32: -2
A33: Criação de materiais de divulgação e campanhas em mídias sociais | B33: =C31 -> 45959 | C33: =B33+D33 -> 45964 | D33: 5 | K33: 3 | L33: -2 | O33: 7 | P33: -2 | S33: 7 | T33: -2 | V33: 3 | W33: -2 | Z33: 45943 | AA33: 0 | AD33: 45943 | AE33: 2 | AH33: 45946 | AI33: 2 | AL33: 45950 | AM33: 2 | AQ33: 45959 | AR33: 2
A34: Treinamento da equipe e apresentação ao público | B34: =C33 -> 45964 | C34: =B34+D34 -> 45968 | D34: 4 | Z34: 5 | AA34: -2 | AB34: 0 | AD34: 45946 | AE34: 0 | AH34: 45950 | AI34: 0 | AL34: 45954 | AM34: 0 | AQ34: 45964 | AR34: 0
A35: Avaliação de resultados, novas parcerias e expansão do projeto | B35: =C34 -> 45968 | C35: =B35+D35 -> 45971 | D35: 3 | K35: Escolha de tecnologias, ferramentas e arquitetura do sistema | O35: Ajustes e refinamentos baseados em feedbacks | AD35: 3 | AE35: -2 | AH35: 4 | AI35: -2 | AL35: 4 | AM35: -2 | AQ35: 5 | AR35: -2
K36: 1 | O36: 11 | AU36: Avaliação de resultados, novas parcerias e expansão do projeto
K37: 45882 | L37: 2 | O37: 45900 | P37: 2 | V37: Integração com sistemas externos e simulação de dados | AU37: 3
K38: 45883 | L38: 0 | O38: 45911 | P38: 0 | V38: 6 | AL38: Atualizações e melhorias contínuas | AU38: 45968 | AV38: 2
K39: 1 | L39: -2 | O39: 11 | P39: -2 | V39: 45927 | W39: 2 | AM39: 5 | AU39: 45971 | AV39: 0
V40: 45933 | W40: 0 | AL40: 45954 | AM40: 2 | AU40: 3 | AV40: -2
K41: Estruturação do cronograma, WBS, marcos e análise de riscos | V41: 6 | W41: -2 | AL41: 45959 | AM41: 0
K42: 5 | AL42: 5 | AM42: -2
K43: 45884 | L43: 2
K44: 45889 | L44: 0
K45: 5 | L45: -2 | V45: Implementação de funcionalidades inteligentes (IA, alertas e exportações)
V46: 5
V47: 45933 | W47: 2
...

Sheet WBS Detalhado
D5: Código | E5: Atividade | F5: Responsável | G5: Recursos Utilizados | H5: Duração (dias) | I5: Início | J5: Término
D6: 1 | E6: Iniciação e Planejamento | F6: Gabriel (Gerente de Projeto) | G6: Reuniões, Documentos, Google Drive, Miro | H6: 15 | I6: 45665 | J6: 16/08/2025
D7: 1.1 | E7: Definição dos objetivos do projeto | F7: Gabriel | G7: Documento de escopo, Google Docs | H7: 2 | I7: 16/08/2025 | J7: 18/08/2025
D8: 1.2 | E8: Formação de equipe e definição de papéis | F8: Adriano | G8: Planilha de equipe, Reunião inicial | H8: 2 | I8: 45724 | J8: 45755
D9: 1.3 | E9: Levantamento de requisitos e stakeholders | F9: Gabriel e Cauã | G9: Formulários, Entrevistas, Miro | H9: 4 | I9: 45785 | J9: 45877
D10: 1.4 | E10: Estruturação do cronograma e WBS | F10: Gabriel | G10: Excel, ProjectLibre | H10: 3 | I10: 45908 | J10: 45969
D11: 1.5 | E11: Levantamento de riscos e marcos de entrega | F11: Matheus | G11: Planilha de riscos, reuniões | H11: 4 | I11: 45999 | J11: 15/08/2025
D12: 2 | E12: Design e Prototipagem | F12: Cauã (Gerente de Comunicação) | G12: Figma, Canva, Google Forms | H12: 12 | I12: 16/08/2025 | J12: 28/08/2025
D13: 2.1 | E13: Criação de protótipos UI/UX | F13: Cauã | G13: Figma, biblioteca de ícones | H13: 4 | I13: 16/08/2025 | J13: 19/08/2025
D14: 2.2 | E14: Pesquisa de usuário e jornada do cliente | F14: Karol | G14: Google Forms, entrevistas | H14: 3 | I14: 20/08/2025 | J14: 22/08/2025
D15: 2.3 | E15: Validação de usabilidade com stakeholders | F15: Adriano | G15: Reunião, feedbacks, Miro | H15: 3 | I15: 23/08/2025 | J15: 25/08/2025
D16: 2.4 | E16: Ajustes e refinamentos pós-feedback | F16: Cauã | G16: Figma, relatórios de feedback | H16: 3 | I16: 26/08/2025 | J16: 28/08/2025
D17: 3 | E17: Desenvolvimento | F17: Gabriel (Gerente de Projeto) | G17: VS Code, SQLite, React, GitHub | H17: 26 | I17: 29/08/2025 | J17: 23/09/2025
D18: 3.1 | E18: Modelagem de dados e criação do modelo ER | F18: Matheus | G18: Draw.io, SQL Designer | H18: 4 | I18: 29/08/2025 | J18: 45666
D19: 3.2 | E19: Implementação no SQLite | F19: Gabriel | G19: SQLite Studio, SQL scripts | H19: 3 | I19: 45697 | J19: 45756
D20: 3.3 | E20: Desenvolvimento do Back-end e API | F20: Gabriel | G20: Node.js, Express, Postman | H20: 7 | I20: 45786 | J20: 45970
D21: 3.4 | E21: Desenvolvimento do Front-end (React) | F21: Gabriel | G21: React, HTML/CSS, Vite | H21: 6 | I21: 46000 | J21: 17/09/2025
D22: 3.5 | E22: Integração com sistemas e simulação de dados | F22: Matheus | G22: Python, datasets simulados | H22: 4 | I22: 18/09/2025 | J22: 21/09/2025
D23: 3.6 | E23: Teste interno e correção de falhas básicas | F23: Adriano | G23: GitHub, logs de teste | H23: 2 | I23: 22/09/2025 | J23: 23/09/2025
D24: 4 | E24: Testes e Lançamento Interno | F24: Karol (Gerente de RH) | G24: GitHub Pages, Navegadores, Documentação | H24: 14 | I24: 24/09/2025 | J24: 45848
D25: 4.1 | E25: Teste de responsividade (desktop e mobile) | F25: Cauã | G25: Ferramentas DevTools | H25: 3 | I25: 24/09/2025 | J25: 26/09/2025
D26: 4.2 | E26: Teste de segurança e desempenho | F26: Adriano | G26: Postman, Lighthouse | H26: 4 | I26: 27/09/2025 | J26: 30/09/2025
D27: 4.3 | E27: Correção de bugs | F27: Gabriel e Matheus | G27: GitHub Issues | H27: 3 | I27: 45667 | J27: 45726
D28: 4.4 | E28: Documentação técnica e hospedagem | F28: Gabriel | G28: GitHub Pages, README.md | H28: 2 | I28: 45757 | J28: 45787
D29: 4.5 | E29: Deploy interno e reunião de aprovação | F29: Equipe | G29: Google Meet, documentação | H29: 2 | I29: 45818 | J29: 45848
D30: 5 | E30: Pós-lançamento e Marketing | F30: Cauã (Gerente de Comunicação) | G30: Canva, Instagram, PowerPoint | H30: 14 | I30: 45879 | J30: 21/10/2025
D31: 5.1 | E31: Monitoramento de métricas e feedbacks | F31: Matheus | G31: Google Analytics, relatórios | H31: 3 | I31: 45879 | J31: 45940
D32: 5.2 | E32: Criação de materiais de apresentação | F32: Cauã | G32: Canva, PowerPoint | H32: 3 | I32: 45971 | J32: 13/10/2025
D33: 5.3 | E33: Treinamento da equipe e divulgação | F33: Karol | G33: Google Meet, Slides | H33: 3 | I33: 14/10/2025 | J33: 16/10/2025
D34: 5.4 | E34: Campanhas em mídias sociais | F34: Cauã | G34: Instagram Ads, Meta Business | H34: 4 | I34: 17/10/2025 | J34: 21/10/2025
D35: 6 | E35: Avaliação e Expansão | F35: Matheus (Gerente Financeiro) | G35: Excel, Relatórios, Reuniões | H35: 14 | I35: 22/10/2025 | J35: 45941
D36: 6.1 | E36: Análise de resultados e custos | F36: Matheus | G36: Planilhas, gráficos financeiros | H36: 4 | I36: 22/10/2025 | J36: 25/10/2025
D37: 6.2 | E37: Identificação de oportunidades de melhoria | F37: Adriano | G37: Reuniões, feedbacks | H37: 4 | I37: 26/10/2025 | J37: 29/10/2025
D38: 6.3 | E38: Planejamento de expansão e novas parcerias | F38: Cauã e Karol | G38: Reuniões externas, propostas | H38: 5 | I38: 30/10/2025 | J38: 45758
D39: 6.4 | E39: Atualizações e novas implementações | F39: Equipe | G39: GitHub, documentação | H39: 5 | I39: 45788 | J39: 45941

Sheet Plano comunicação
C3: Etapa | D3: Atividade | E3: Objetivo da Comunicação
C5: Iniciação e Planejamento | D5: Reunião de abertura do projeto | E5: Apresentar o escopo, objetivos e cronograma do projeto
C7: Design e Prototipagem | D7: Apresentação do design e protótipos | E7: Validar identidade visual e fluxos de navegação com a equipe e stakeholders internos | I7: Público-Alvo | J7: Meio de Comunicação | K7: Frequência | L7: Responsável | M7: Início | N7: Término | O7: Recursos Necessários
I8: Stakeholders e equipe interna | J8: Reunião inicial (Google Meet e e-mail) | K8: Uma vez no início | L8: Gabriel (Gerente de Projeto) | M8: 45665 | N8: 45724 | O8: Computador, Google Meet, slides, e-mail
C9: Desenvolvimento | D9: Relatório de progresso técnico | E9: Atualizar status de desenvolvimento, desafios e entregas
I10: Equipe de design e comunicação | J10: Reuniões via Figma e Miro, e-mails de feedback | K10: A cada nova versão do protótipo | L10: Cauã (Gerente de Comunicação) | M10: 45755 | N10: 15/08/2025 | O10: Figma, Canva, Google Drive
C11: Testes e Lançamento Interno | D11: Divulgação de resultados dos testes internos | E11: Comunicar resultados dos testes e correções aplicadas
I12: Equipe técnica e gerente de projeto | J12: Reuniões semanais e relatórios no Google Docs | K12: Semanalmente | L12: Gabriel (Gerente de Projeto) | M12: 16/08/2025 | N12: 30/09/2025 | O12: VS Code, GitHub, Google Docs
C13: Pós-lançamento e Marketing | D13: Campanha de divulgação nas redes sociais | E13: Promover o projeto e aumentar o alcance do público externo
I14: Equipe de desenvolvimento e RH | J14: Reuniões e planilhas compartilhadas | K14: Após cada rodada de testes | L14: Karol (Gerente de RH) | M14: 45667 | N14: 15/10/2025 | O14: GitHub, planilhas, relatórios
C15: Avaliação e Expansão | D15: Relatório final e reunião de resultados | E15: Apresentar métricas de desempenho e oportunidades de melhoria
I16: Público externo e parceiros | J16: Redes sociais, e-mail marketing, apresentações | K16: 1 semana após o lançamento | L16: Cauã (Gerente de Comunicação) | M16: 16/10/2025 | N16: 31/10/2025 | O16: Canva, Instagram, PowerPoint, Meta Ads
I18: Stakeholders e equipe de projeto | J18: Reunião final e dashboards de resultados | K18: Mensalmente até o encerramento | L18: Matheus (Gerente Financeiro) | M18: 45668 | N18: 45941 | O18: Planilhas, Google Analytics, dashboards

Sheet Gestão Custo
C9: Etapa | D9: Descrição do Custo | E9: Tipo de Custo | F9: Responsável | G9: Valor Estimado (R$) | H9: Valor Realizado (R$) | I9: Data Início | J9: Data Término | K9: Status | L9: Recursos Utilizados | M9: Observações
C10: Iniciação e Planejamento | D10: Reuniões iniciais, elaboração de documentos e registro do projeto | E10: Administrativo | F10: Gabriel | G10: 2 | H10: 1.9 | I10: 45665 | J10: 45938 | K10: Concluído | L10: Google Meet, Office 365, Coffee break | M10: Reuniões com stakeholders e patrocinadores
C11: Definição de Requisitos | D11: Mapeamento de funcionalidades e levantamento técnico | E11: Técnico | F11: Gabriel | G11: 2.2 | H11: 2.1 | I11: 45969 | J11: 18/08/2025 | K11: Concluído | L11: Google Docs, Miro, Notion | M11: Documentos de escopo e backlog do projeto
C12: Design UI/UX | D12: Criação de identidade visual, wireframes e protótipos | E12: Ferramentas de Design | F12: Cauã | G12: 3.5 | H12: 3.8 | I12: 19/08/2025 | J12: 31/08/2025 | K12: Concluído | L12: Figma Pro, Canva Premium, Google Drive | M12: Foram feitos 2 ciclos de feedback
C13: Desenvolvimento Back-end | D13: Criação de APIs, autenticação e banco de dados | E13: Tecnologia | F13: Adriano | G13: 5.5 | H13: 5.7 | I13: 45666 | J13: 20/09/2025 | K13: Em andamento | L13: SQLite, Node.js, VS Code, GitHub | M13: Integração com módulo de métricas
C14: Desenvolvimento Front-end | D14: Criação de dashboard e componentes interativos | E14: Tecnologia | F14: Gabriel | G14: 4 | H14: 3.9 | I14: 15/09/2025 | J14: 25/09/2025 | K14: Em andamento | L14: React.js, Tailwind, Recharts, Canva | M14: Integração parcial com API
C15: Testes Funcionais e de Segurança | D15: Testes de interface, desempenho e vulnerabilidades | E15: QA e Infra | F15: Adriano | G15: 2.8 | H15: 2.5 | I15: 26/09/2025 | J15: 45787 | K15: Planejado | L15: Postman, Jest, OWASP Scanner | M15: Testes com usuários internos
C16: Lançamento e Documentação | D16: Deploy do sistema e manual de uso | E16: Tecnologia / Comunicação | F16: Gabriel e Cauã | G16: 1.6 | H16: 1.5 | I16: 45818 | J16: 15/10/2025 | K16: Planejado | L16: GitHub Pages, Google Docs | M16: Deploy interno para stakeholders
C17: Marketing e Divulgação | D17: Criação de campanhas e material de apresentação | E17: Marketing | F17: Cauã | G17: 3 | H17: 3.2 | I17: 16/10/2025 | J17: 25/10/2025 | K17: Planejado | L17: Canva, Meta Ads, Instagram, PowerPoint | M17: Divulgação do lançamento do sistema
C18: Treinamentos e RH | D18: Onboarding e treinamento da equipe | E18: Recursos Humanos | F18: Karol | G18: 1.5 | H18: 1.3 | I18: 45818 | J18: 20/10/2025 | K18: Planejado | L18: Google Meet, PDFs, vídeos explicativos | M18: Cursos rápidos de suporte ao sistema
C19: Encerramento e Avaliação | D19: Reunião final e relatórios financeiros | E19: Financeiro | F19: Matheus | G19: 1.2 | H19: 1.1 | I19: 26/10/2025 | J19: 45941 | K19: Pendente | L19: Excel, Google Sheets, Apresentação final | M19: Fechamento de custos e lições aprendidas

Sheet OrçadoXRealizado
G10: Categoria | H10: Descrição | I10: Responsável | J10: Orçado (R$) | K10: Realizado (R$) | L10: Diferença (R$) | M10: % Execução | N10: Justificativa | O10: Status
G11: Planejamento | H11: Documentos, reuniões e ferramentas iniciais | I11: Gabriel | J11: 2 | K11: 1.9 | L11: 100 | M11: 0.95 | N11: Menor gasto com locação de sala | O11: Concluído
G12: Requisitos e Design | H12: Definição de requisitos e design visual | I12: Cauã | J12: 5.7 | K12: 5.9 | L12: -200 | M12: 1.04 | N12: Upgrade para Figma Pro e feedback extra | O12: Concluído
G13: Desenvolvimento | H13: APIs, front-end e integrações | I13: Adriano | J13: 9.5 | K13: 9.6 | L13: -100 | M13: 1.01 | N13: Pequenos ajustes no servidor | O13: Em andamento
G14: Testes e Segurança | H14: Testes automatizados e infraestrutura | I14: Gabriel | J14: 2.8 | K14: 2.5 | L14: 300 | M14: 0.89 | N14: Testes concluídos antes do previsto | O14: Planejado
G15: Marketing e Divulgação | H15: Campanhas digitais e materiais visuais | I15: Cauã | J15: 3 | K15: 3.2 | L15: -200 | M15: 1.06 | N15: Maior investimento em anúncios pagos | O15: Planejado
G16: Recursos Humanos | H16: Treinamento e capacitação da equipe | I16: Karol | J16: 1.5 | K16: 1.3 | L16: 200 | M16: 0.87 | N16: Parte do treinamento foi assíncrono | O16: Planejado
G17: Encerramento e Relatórios | H17: Reunião de fechamento e documentação | I17: Matheus | J17: 1.2 | K17: 1.1 | L17: 100 | M17: 0.92 | N17: Otimização dos custos de impressão | O17: Pendente
G18: Total Geral | H18: - | I18: - | J18: 25.7 | K18: 25.5 | L18: 200 | M18: 0.99 | N18: Pequena economia geral no orçamento | O18: Em execução

Sheet Analise de risco 
D4: ID | E4: Risco | F4: Probabilidade (1-5) | G4: Impacto (1-5) | H4: Nível de Risco (P x I) | I4: Classificação | J4: Ação Preventiva | K4: Ação Corretiva | L4: Responsável | M4: Status
D5: R1 | E5: Atraso na entrega do front-end | F5: 3 | G5: 4 | H5: 12 | I5: Alto | J5: Revisar cronograma semanal | K5: Redistribuir tarefas entre equipe | L5: Gabriel | M5: Ativo
D6: R2 | E6: Falhas no banco de dados | F6: 2 | G6: 5 | H6: 10 | I6: Alto | J6: Backup diário e testes automatizados | K6: Recuperação de dados e correção de script | L6: Adriano | M6: Controlado
D7: R3 | E7: Falta de engajamento da equipe | F7: 2 | G7: 3 | H7: 6 | I7: Médio | J7: Reuniões motivacionais e feedbacks | K7: Reforçar comunicação e redefinir metas | L7: Karol | M7: Monitorado
D8: R4 | E8: Problemas de comunicação com stakeholders | F8: 3 | G8: 2 | H8: 6 | I8: Médio | J8: Calendário fixo de reuniões | K8: E-mails e relatórios semanais | L8: Cauã | M8: Controlado
D9: R5 | E9: Orçamento estourado | F9: 2 | G9: 4 | H9: 8 | I9: Alto | J9: Avaliar gastos antes da execução | K9: Revisão orçamentária | L9: Matheus | M9: Em observação
D10: R6 | E10: Falhas em campanhas de marketing | F10: 3 | G10: 3 | H10: 9 | I10: Médio | J10: Teste A/B de campanhas | K10: Revisão de conteúdo e estratégia | L10: Cauã | M10: Planejado
D11: R7 | E11: Perda de documentos técnicos | F11: 1 | G11: 5 | H11: 5 | I11: Médio | J11: Backup na nuvem | K11: Gerenciamento via Google Drive | L11: Gabriel | M11: Controlado
D12: R8 | E12: Rotatividade de membros | F12: 2 | G12: 3 | H12: 6 | I12: Médio | J12: Documentação e plano de substituição | K12: Treinamento rápido e integração | L12: Karol | M12: Pendente

Sheet Histórico de Risco
D6: Etapa | E6: Risco | F6: Ação Preventiva / Mitigadora | G6: Resultado | H6: Status | I6: Responsável | J6: Data
D7: Iniciação e Planejamento | E7: Falha na comunicação entre membros | F7: Implantação de reuniões semanais e uso de Google Chat | G7: Comunicação estruturada e alinhamento melhorado | H7: Resolvido | I7: Gabriel | J7: 45665
D8: Iniciação e Planejamento | E8: Atraso na definição do escopo | F8: Reunião extra com o patrocinador e priorização de entregas | G8: Escopo fechado dentro do prazo | H8: Resolvido | I8: Adriano | J8: 45877
D9: Design e Prototipagem | E9: Retrabalho por divergência entre design e usabilidade | F9: Validação dos protótipos com stakeholders | G9: Redução de retrabalho em 60% | H9: Controlado | I9: Cauã | J9: 15/08/2025
D10: Design e Prototipagem | E10: Atrasos no feedback dos stakeholders | F10: Definição de prazos fixos de retorno e acompanhamento | G10: Atrasos pontuais, sem impacto no cronograma | H10: Em monitoramento | I10: Cauã | J10: 25/08/2025
D11: Desenvolvimento | E11: Falhas na integração entre front-end e back-end | F11: Testes unitários e reuniões técnicas diárias | G11: Erros críticos reduzidos em 80% | H11: Controlado | I11: Gabriel | J11: 45939
D12: Desenvolvimento | E12: Sobrecarga de tarefas sobre o gerente técnico | F12: Redistribuição de atividades e replanejamento | G12: Redução da sobrecarga e manutenção do prazo | H12: Resolvido | I12: Karol | J12: 18/09/2025
D13: Desenvolvimento | E13: Instabilidade do ambiente de desenvolvimento | F13: Migração do servidor local para AWS gratuita | G13: Estabilidade aumentada e tempo de resposta reduzido em 35% | H13: Resolvido | I13: Gabriel | J13: 25/09/2025
D14: Testes e Lançamento | E14: Vulnerabilidades na autenticação de usuários | F14: Revisão de segurança e criptografia | G14: Falha eliminada e sistema aprovado | H14: Resolvido | I14: Gabriel | J14: 28/09/2025
D15: Testes e Lançamento | E15: Falta de tempo hábil para correções | F15: Ampliação da equipe temporária de QA | G15: Correções concluídas com antecedência | H15: Resolvido | I15: Karol | J15: 45787
D16: Marketing e Pós-lançamento | E16: Baixo engajamento das campanhas digitais | F16: Ajuste de público-alvo e novas estratégias | G16: Engajamento aumentado em 22% | H16: Controlado | I16: Adriano | J16: 15/10/2025
D17: Marketing e Pós-lançamento | E17: Dificuldade na coleta de feedbacks | F17: Criação de formulário online no dashboard | G17: Mais de 50 respostas coletadas em 48h | H17: Resolvido | I17: Cauã | J17: 25/10/2025
D18: Marketing e Pós-lançamento | E18: Custo das campanhas superior ao previsto | F18: Replanejamento orçamentário e realocação de verba | G18: Impacto financeiro reduzido a 4,6% | H18: Controlado | I18: Matheus | J18: 45788

Sheet Gráfico de Gantt
E3: Saúde e bem-estar na palma da sua mão
A5: Insira o nome do Líder do projeto na célula B3. Insira a data de Início do projeto na célula E3. Início do projeto: o rótulo está na célula C3. | D5: Líder do projeto: Gerente de Projeto | E5: Início do projeto: | G5: 45160
A6: A semana de exibição na célula E4 representa a semana inicial a ser exibida no cronograma do projeto na célula I4. A data de início do projeto é considerada Semana 1. Para alterar a semana de exibição, basta inserir um novo número da semana na célula E4. A data inicial para cada semana, começando com a semana de exibição na célula E4, começa na célula I4 e é calculada automaticamente. Há 8 semanas representadas nesse modo de exibição que vão da célula I4 a célula BF4. Você não deve modificar essas células. Semana de exibição: o rótulo está na célula C4. | E6: Semana de exibição: | G6: 1 | K6: =K7 -> 45159 | R6: =R7 -> 45166 | Y6: =Y7 -> 45173 | AF6: =AF7 -> 45180 | AM6: =AM7 -> 45187 | AT6: =AT7 -> 45194 | BA6: =BA7 -> 45201 | BH6: =BH7 -> 45208
A7: As células I5 a BL5 contêm o número de dias da semana representado no bloco de células acima de cada célula de data e são calculadas automaticamente. Você não deve modificar essas células. A data de hoje é contornada em vermelho (hex #AD3815) a partir da data de hoje na linha 5, passando pela coluna de data inteira até o final do cronograma do projeto. | K7: =Início_do_projeto-WEEKDAY(Início_do_projeto,1)+2+7*(Semana_de_exibição-1) -> 45159 | L7: =K7+1 -> 45160 | M7: =L7+1 -> 45161 | N7: =M7+1 -> 45162 | O7: =N7+1 -> 45163 | P7: =O7+1 -> 45164 | Q7: =P7+1 -> 45165 | R7: =Q7+1 -> 45166 | S7: =R7+1 -> 45167 | ... BN7: =BM7+1 -> 45214
A8: Esta linha inclui cabeçalhos do cronograma do projeto que estão abaixo deles. Navegue de B6 a BL6 para ouvir o conteúdo. A primeira letra de cada dia da semana da data acima daquele cabeçalho começa na célula I6 e continua até a célula BL6. Todo o gráfico de linha do tempo de projeto é gerado automaticamente com base nas datas de início e término inseridas, usando os formatos condicionais. Não modifique o conteúdo nas células dentro das colunas após a coluna I, começando na célula I7. | D8: TAREFA | E8: ATRIBUÍDO PARA | F8: PROGRESSO | G8: INÍCIO | H8: TÉRMINO | J8: DIAS | K8: =LEFT(TEXT(K7,"ddd"),1) -> s | L8: =LEFT(TEXT(L7,"ddd"),1) -> t | M8: =LEFT(TEXT(M7,"ddd"),1) -> q | N8: =LEFT(TEXT(N7,"ddd"),1) -> q | O8: =LEFT(TEXT(O7,"ddd"),1) -> s | P8: =LEFT(TEXT(P7,"ddd"),1) -> s | Q8: =LEFT(TEXT(Q7,"ddd"),1) -> d | R8: =LEFT(TEXT(R7,"ddd"),1) -> s | ... BN8: =LEFT(TEXT(BN7,"ddd"),1) -> d
A9: Não exclua esta linha. Esta linha ficará oculta para preservar uma fórmula usada para realçar o dia atual no cronograma do projeto. | J9: =IF(OR(ISBLANK(início_da_tarefa),ISBLANK(término_da_tarefa)),"",término_da_tarefa-início_da_tarefa+1) -> 4
A10: A célula B8 contém o título do exemplo da Fase 1. Insira um novo Título na célula B8. Na célula C8, insira o nome a atribuir à fase, caso ela se aplique ao seu projeto. Na célula D8, insira o Progresso para a fase inteira, caso ela se aplique ao seu projeto. Nas células E8 e F8, insira as datas de início e término para a fase inteira, caso ela se aplique ao seu projeto. O gráfico de Gantt preenche automaticamente as datas apropriadas e sombreia de acordo com o andamento inserido. Para excluir a fase e trabalhar apenas nas tarefas, basta excluir essa linha. | D10: Iniciação | J10: =IF(OR(ISBLANK(início_da_tarefa),ISBLANK(término_da_tarefa)),"",término_da_tarefa-início_da_tarefa+1) -> 3
A11: A célula B9 contém a tarefa de exemplo "Tarefa 1". Insira um novo nome da tarefa na célula B9. Insira uma pessoa para atribuir a tarefa na célula C9. Insira o andamento da tarefa na célula D9. Uma barra de progresso é exibida na célula e fica sombreada de acordo com o número na célula. Por exemplo, 50% de progresso sombreia metade da célula. Insira a data de início da tarefa na célula E9. Insira a data de término da tarefa na célula F9. Uma barra de status sombreada das datas inseridas aparece em blocos começando na célula I9 até BL9. | D11: Definir os objetivos do aplicativo e sua proposta de valor | G11: =Início_do_projeto -> 45160 | H11: =G11+3 -> 45163 | J11: =IF(OR(ISBLANK(início_da_tarefa),ISBLANK(término_da_tarefa)),"",término_da_tarefa-início_da_tarefa+1) -> 5
A12: As linhas 10 a 13 repetem o padrão da linha 9. Repita as instruções da célula A9 para todas as linhas de tarefas nesta planilha. Substitua os dados de exemplo. Um exemplo de outra fase começa na célula A14. Continue inserindo tarefas nas células A10 a A13 ou vá para a célula A14 para saber mais. | D12: Tarefa 2 | J12: =IF(OR(ISBLANK(início_da_tarefa),ISBLANK(término_da_tarefa)),"",término_da_tarefa-início_da_tarefa+1) -> 6
D13: Tarefa 3 | J13: =IF(OR(ISBLANK(início_da_tarefa),ISBLANK(término_da_tarefa)),"",término_da_tarefa-início_da_tarefa+1) -> 3
D14: Tarefa 4 | J14: =IF(OR(ISBLANK(início_da_tarefa),ISBLANK(término_da_tarefa)),"",término_da_tarefa-início_da_tarefa+1)
D15: Tarefa 5 | J15: =IF(OR(ISBLANK(início_da_tarefa),ISBLANK(término_da_tarefa)),"",término_da_tarefa-início_da_tarefa+1) -> 5
A16: A célula à direita contém o título do exemplo da Fase 2. Você pode criar uma nova fase a qualquer momento na coluna B. Este cronograma de projeto não exige fases. Para remover a fase, basta excluir a linha. Para criar um novo bloco de fases nesta linha, digite um novo Título na célula à direita. Para continuar a adicionar tarefas à fase acima, insira uma nova linha acima desta e preencha os dados da tarefa como na instrução da célula A9. Atualize os detalhes da Fase na célula à direita, com base nas instruções da célula A8. Continue navegando para baixo nas células da coluna A para saber mais. Se você ainda não adicionou as novas linhas nesta planilha, encontrará 2 exemplos adicionais de blocos de fase que foram criados nas células B20 e B26. Caso contrário, navegue pelas células da coluna A para localizar os blocos adicionais. Repita as instruções das células A8 e A9 sempre que precisar. | D16: Título Fase 2 | J16: =IF(OR(ISBLANK(início_da_tarefa),ISBLANK(término_da_tarefa)),"",término_da_tarefa-início_da_tarefa+1) -> 6
D17: Tarefa 1 | J17: =IF(OR(ISBLANK(início_da_tarefa),ISBLANK(término_da_tarefa)),"",término_da_tarefa-início_da_tarefa+1) -> 4
D18: Tarefa 2 | J18: =IF(OR(ISBLANK(início_da_tarefa),ISBLANK(término_da_tarefa)),"",término_da_tarefa-início_da_tarefa+1) -> 3
D19: Tarefa 3 | J19: =IF(OR(ISBLANK(início_da_tarefa),ISBLANK(término_da_tarefa)),"",término_da_tarefa-início_da_tarefa+1) -> 4
D20: Tarefa 4 | J20: =IF(OR(ISBLANK(início_da_tarefa),ISBLANK(término_da_tarefa)),"",término_da_tarefa-início_da_tarefa+1)
D21: Tarefa 5 | J21: =IF(OR(ISBLANK(início_da_tarefa),ISBLANK(término_da_tarefa)),"",término_da_tarefa-início_da_tarefa+1) -> 6
A22: Bloco de título de fase de exemplo | D22: Título Fase 3 | J22: =IF(OR(ISBLANK(início_da_tarefa),ISBLANK(término_da_tarefa)),"",término_da_tarefa-início_da_tarefa+1) -> 5
D23: Tarefa 1 | J23: =IF(OR(ISBLANK(início_da_tarefa),ISBLANK(término_da_tarefa)),"",término_da_tarefa-início_da_tarefa+1) -> 6
D24: Tarefa 2 | J24: =IF(OR(ISBLANK(início_da_tarefa),ISBLANK(término_da_tarefa)),"",término_da_tarefa-início_da_tarefa+1) -> 5
D25: Tarefa 3 | J25: =IF(OR(ISBLANK(início_da_tarefa),ISBLANK(término_da_tarefa)),"",término_da_tarefa-início_da_tarefa+1) -> 5
D26: Tarefa 4 | J26: =IF(OR(ISBLANK(início_da_tarefa),ISBLANK(término_da_tarefa)),"",término_da_tarefa-início_da_tarefa+1)
D27: Tarefa 5 | J27: =IF(OR(ISBLANK(início_da_tarefa),ISBLANK(término_da_tarefa)),"",término_da_tarefa-início_da_tarefa+1) -> #VALUE!
A28: Bloco de título de fase de exemplo | D28: Título Fase 4 | J28: =IF(OR(ISBLANK(início_da_tarefa),ISBLANK(término_da_tarefa)),"",término_da_tarefa-início_da_tarefa+1) -> #VALUE!
D29: Tarefa 1 | G29: data | H29: data | J29: =IF(OR(ISBLANK(início_da_tarefa),ISBLANK(término_da_tarefa)),"",término_da_tarefa-início_da_tarefa+1) -> #VALUE!
D30: Tarefa 2 | G30: data | H30: data | J30: =IF(OR(ISBLANK(início_da_tarefa),ISBLANK(término_da_tarefa)),"",término_da_tarefa-início_da_tarefa+1) -> #VALUE!
D31: Tarefa 3 | G31: data | H31: data | J31: =IF(OR(ISBLANK(início_da_tarefa),ISBLANK(término_da_tarefa)),"",término_da_tarefa-início_da_tarefa+1) -> #VALUE!
D32: Tarefa 4 | G32: data | H32: data | J32: =IF(OR(ISBLANK(início_da_tarefa),ISBLANK(término_da_tarefa)),"",término_da_tarefa-início_da_tarefa+1)
D33: Tarefa 5 | G33: data | H33: data | J33: =IF(OR(ISBLANK(início_da_tarefa),ISBLANK(término_da_tarefa)),"",término_da_tarefa-início_da_tarefa+1)
A34: Esta é uma linha vazia | J34: =IF(OR(ISBLANK(início_da_tarefa),ISBLANK(término_da_tarefa)),"",término_da_tarefa-início_da_tarefa+1)
A35: Esta linha marca o final do Cronograma do projeto. NÃO insira nada nessa linha. Insira novas linhas ACIMA desta linha para continuar a construção do cronograma de projeto. | D35: Insira novas linhas ACIMA desta | J35: =IF(OR(ISBLANK(início_da_tarefa),ISBLANK(término_da_tarefa)),"",término_da_tarefa-início_da_tarefa+1)

Sheet PV_dependência
A3: Soma de Custos
A4: Dependência | B4: Responsável | C4: Etapas – Atividades - | D4: Ref | E4: Total
A5: 1.1 | B5: GERENTE DE PROJETO | C5: Definir os objetivos do aplicativo e sua proposta de valor | D5: 1.1 | E5: 1000
C6: Formar uma equipe de desenvolvimento e design | D6: 1.3 | E6: 1000
C7: Identificar as principais funcionalidades e recursos a serem incluídos | D7: 1.2 | E7: 2000
A8: 1.3 | B8: DESIGN | C8: Realizar o design da interface do usuário (UI) | D8: 3.1 | E8: 2000
B9: GERENTE DE PROJETO | C9: Definir os requisitos detalhados do aplicativo (escopo) | D9: 2.2 | E9: 700
B10: (vazio) | C10: Planejamento | D10: 2
A11: 10.1.1 | B11: DESEMPENHO | C11: Realizar análises regulares sobre o desempenho do aplicativo | D11: 10.1.1 | E11: 4000
A12: 10.1.2 | B12: COMERCIAL | C12: Explorar parcerias com empresas relacionadas à saúde e bem-estar | D12: 10.1.2 | E12: 1000
A13: 10.1.3 | B13: COMERCIAL | C13: Avaliar a possibilidade de oferecer versões premium ou modelos de assinatura | D13: 10.1.3 | E13: 1000
A14: 2.1 | B14: GERENTE DE PROJETO | C14: Realizar uma análise de mercado para entender concorrentes e demandas | D14: 2.1 | E14: 2000
A15: 2.2 | B15: GERENTE DE PROJETO | C15: Criar um cronograma detalhado com marcos e prazos | D15: 2.3 | E15: 400
C16: Dicas de saúde e bem-estar | D16: 2.2.1 | E16: 500
C17: Integração com sistemas de monitoramento de saúde | D17: 2.2.4 | E17: 200
C18: Mapas com locais de academias e parques | D18: 2.2.3 | E18: 800
C19: Planos de exercícios físicos personalizados | D19: 2.2.2 | E19: 1000
A20: 2.3 | B20: (vazio) | C20: Design e Prototipagem | D20: 3
A21: 3.1 | B21: DESIGN | C21: Navegação simples entre as funcionalidades | D21: 3.1.1 | E21: 500
A22: 3.1.1 | B22: DESIGN | C22: Criar protótipos interativos para validar o fluxo de usuário | D22: 3.1.2 | E22: 500
A23: 3.1.2 | B23: DESIGN | C23: Experiência do usuário (UX) | D23: 3.2 | E23: 1000
A24: 3.2 | B24: DESIGN | C24: Interface limpa e intuitiva | D24: 3.2.1 | E24: 500
A25: 3.2.1 | B25: (vazio) | C25: Desenvolvimento | D25: 4
A26: 3.2.2 | B26: DESIGN | C26: Teste de UI / UX | D26: 3.2.2 | E26: 700
A27: 4.1 | B27: DESENVOLVIMENTO | C27: Desenvolver a estrutura do aplicativo | D27: 4.1 | E27: 500
A28: 4.1.2 | B28: DESENVOLVIMENTO | C28: Front-end: Interface do usuário e interações | D28: 4.1.2 | E28: 5000
A29: 4.2 | B29: DESENVOLVIMENTO | C29: Implementar as funcionalidades principais | D29: 4.2 | E29: 700
A30: 4.2.1 | B30: DESENVOLVIMENTO | C30: Módulo de dicas de saúde | D30: 4.2.1 | E30: 500
A31: 4.2.2 | B31: DESENVOLVIMENTO | C31: Gerador de planos de exercícios | D31: 4.2.2 | E31: 300
A32: 4.2.3 | B32: DESENVOLVIMENTO | C32: Integração com APIs de mapas para localização de academias e parques | D32: 4.2.3 | E32: 1000
A33: 5.1 | B33: SEGURANÇA | C33: Integrar o aplicativo com sistemas de monitoramento de saúde, como dispositivos wearable ou aplicativos de rastreamento | D33: 5.1 | E33: 3000
A34: 5.2 | B34: SEGURANÇA | C34: Garantir a segurança e privacidade dos dados do usuário | D34: 5.2 | E34: 1000
A35: 5.3 | B35: SEGURANÇA | C35: Testar a integração para assegurar que os dados são sincronizados corretamente | D35: 5.3 | E35: 1000
A36: 6.1 | B36: QUALIDADE | C36: Realizar testes de qualidade e desempenho em diversas plataformas (iOS, Android) | D36: 6.1 | E36: 30000
A37: 6.1.2 | B37: UX | C37: Testar a usabilidade do aplicativo com usuários reais | D37: 6.1.2 | E37: 700
... A47: 9.1.3 | B47: EQUIPE TÉCNICA | C47: Realizar campanhas de mídia social e anúncios online | D47: 9.1.3 | E47: 10000
A48: (vazio) | B48: (vazio) | C48: Avaliação e Aperfeiçoamento | D48: 10
C49: Iniciação | D49: 1
C50: Integração com sistemas de monitoramento de saúde | D50: 5
C51: Lançamento | D51: 7
...

Sheet Cronograma_de_Custos (2)
B2: 5.2. CRONOGRAMA DE CUSTOS
B5: Ref | C5: Etapas – Atividades - Marcos
D6: 1 | E6: 2 | F6: 3 | G6: 4 | H6: 5 | I6: 6 | J6: 7 | K6: 8 | L6: 9 | M6: 10 | N6: 11 | O6: 12 | P6: 13 | Q6: 14 | R6: 15 | S6: 16 | T6: 17 | U6: 18 | V6: 19 | W6: 20 | X6: 21 | Y6: 22 | Z6: 23 | AA6: 24
D7: Agosto | H7: Setembro | L7: Outubro | P7: Novembro | T7: Dezembro | X7: Janeiro
B8: 1.1 | C8: Plano do Projeto | D8: 30000
B9: 1.2 | C9: Controle | H9: 5000 | L9: 5000 | P9: 5000 | T9: 5000
B10: 1.3 | C10: Fechamento | X10: 10000
B11: 2 | C11: Adequar o Espaço Físico | L11: 20000 | P11: 40000 | T11: 10000 | X11: 10000
B12: 3.1 | C12: Equipamentos de Ginástica | H12: 10000 | L12: 25000 | P12: 25000 | T12: 25000 | X12: 5000
B13: 3.2 | C13: Equipamentos de Apoio e Administração | L13: 15000 | P13: 15000 | T13: 20000 | X13: 10000
B14: 4 | C14: Contratar Mão de Obra | X14: 7000
B15: 5.1 | C15: Contratar empresa para informatização da academia | T15: 4000 | X15: 4000
B16: 5.2 | C16: Adquirir Sistemas de Segurança | T16: 2500 | X16: 2500
B17: 5.3 | C17: Fechar Convênio com Estacionamento próximo ao local | X17: 0
B18: 5.4 | C18: Contratação de Designer de Interiores | H18: =20000*35% -> 7000 | L18: =13000/4 -> 3250 | P18: =13000/4 -> 3250 | T18: =13000/4 -> 3250 | X18: =13000/4 -> 3250

Sheet Organograma da equipe
J5: Gabriel Orlandi
J7: Gerente do Projeto
F12: Matheus Santoro | I12: Cauã William | L12: Karol Lemos | O12: Adriano Xu
F14: Gerente Financeiro | I14: Gerente Comunicação | L14: Gerente de RH | O14: Gerente de TI

Sheet Identificar
A1: Identificação dos Riscos | AF1: Probabilidade | AI1: Impacto
A4: =[4]Capa!E6 -> [sigla do projeto] - Nome do Projeto
AF5: Muito Baixa - 1 | AG5: 1 | AI5: Muito Baixo - 1 | AJ5: 1
A6: ID | B6: Fase ou | D6: Declaração do Risco | G6: Resp. | H6: Estratégia de Resposta | I6: Plano de Prevenção | J6: Plano de Contingência | L6: Severidade (X,Y) | AF6: Baixa - 2 | AG6: 2 | AI6: Muito Baixo - 2 | AJ6: 2
B7: Recurso | C7: Classificação | D7: CAUSA (Começa a frase com "Como Resultado ...") | E7: RISCO (Começar a frase com "Pode ocorrer ...") | F7: CONSEQUÊNCIA (Começar a frase com "O que acarretaria ...") | K7: Riscos Colaterais | AF7: Moderada - 3 | AG7: 3 | AI7: Baixo - 3 | AJ7: 3
A8: R01 | B8: Desenvolvimento | C8: Ausência | D8: Contratação tardia de equipe técnica | E8: Atraso no início do desenvolvimento | F8: Deslizamento de marcos e compressão do cronograma | G8: Replanejar marcos e realocar atividades não críticas | H8: Mitigar | I8: Pipeline de candidatos ,onboarding antecipado | J8: Alocação temporária de terceiros | K8: Atraso no projeto e aumento nos custos | L8: =Qualificar!K8 -> 0.16 | AF8: Alta - 4 | AG8: 4 | AI8: Baixo - 4 | AJ8: 4
A9: R02 | B9: Fornecedores | C9: Custo | D9: Reajustes contratuais e variação cambial | E9: Estouro de orçamento | F9: Redução de escopo e contingenciamento | G9: Repriorizar entregas, acionar reserva gerencial | H9: Mitigar | I9: Cláusulas de teto, múltiplas cotações | J9: Troca de fornecedor/escopo alternativo | L9: =Qualificar!K9 -> 0.08
A10: R03 | B10: Testes | C10: Qualidade | D10: Janela de testes comprimida | E10: Defeitos críticos em produção | F10: Retrabalho e custos adicionais | G10: Gate Go/No-Go até sanar defeitos críticos | H10: Mitigar | I10: Plano de testes por risco; automação | J10: Hotfixes priorizados, war room | L10: =Qualificar!K10 -> 0.08
A11: R04 | B11: Pessoas | C11: Ausência | D11: Ausências e rotatividade | E11: Indisponibilidade de recursos-chave | F11: Queda de produtividade e atrasos | G11: Replanejar sprints e redistribuir tarefas | H11: Mitigar | I11: Plano de backup, documentação; pareamento | J11: Banco de horas, contratação temporária | L11: =Qualificar!K11 -> 0.04
A12: R05 | B12: Integrações | C12: Dependência | D12: SLA de terceiro apertado | E12: Atraso em componentes de integração | F12: Bloqueio de integrações e marcos | G12: Paralelizar tarefas independentes | H12: Mitigar | I12: Acordos de SLA/multa, plano alternativo | J12: Stub/mocks temporários | L12: =Qualificar!K12 -> 0.08
A13: R06 | B13: Escopo | C13: Expectativas | D13: Novas demandas | E13: Aumento de escopo | F13: Pressão em prazo e custo | G13: Acionar CCB e repriorizar backlog | H13: Mitigar | I13: Critérios de aceite, timebox | J13: Fatiar entregas; MVP | L13: =Qualificar!K13 -> 0.64
A14: R07 | B14: Conformidade | C14: Compliance | D14: Interpretação tardia de requisitos | E14: Não conformidade regulatória | F14: Retrabalho e risco reputacional | G14: Bloquear release até conformidade | H14: Evitar | I14: Checklist jurídico, auditorias internas | J14: Task force para adequação urgente | L14: =Qualificar!K14 -> 0.02
A15: R08 | B15: Segurança | C15: Segurança da Informação | D15: Dados reais em testes; acessos excessivos | E15: Vazamento de dados | F15: Sanções e danos reputacionais | G15: Acionar resposta a incidentes; notificar DPO | H15: Mitigar | I15: Anonimização, RBAC, hardening | J15: Isolamento do ambiente, rotação de credenciais | L15: =Qualificar!K15 -> 0.04
A16: R09 | B16: Requisitos | C16: Escopo | D16: Requisitos ambíguos | E16: Entregas fora da necessidade do usuário | F16: Retrabalho e baixa adoção | G16: Refinamento com usuários e correções dirigidas | H16: Mitigar | I16: DoR/DoD, protótipos validáveis | J16: Sprint de correção focada
A17: R10 | B17: Infraestrutura | C17: Desempenho | D17: Capacidade insuficiente de ambiente | E17: Degradação de performance | F17: SLA violado e insatisfação | G17: Escalar recursos; otimização | H17: Mitigar | I17: Testes de carga; auto-scaling | J17: CDN/cache; feature flags
A18: R11 | B18: Treinamento | C18: Falta de Habilidade | D18: Capacitação insuficiente dos usuários | E18: Baixa adoção do sistema | F18: Queda de valor percebido | G18: Capacitação extra pós-go-live | H18: Mitigar | I18: Trilhas de treinamento; materiais práticos | J18: Suporte dedicado temporário
A19: R12 | B19: Dados | C19: Qualidade de Dados | D19: Inconsistências na migração | E19: Erros operacionais pós-go-live | F19: Interrupções e retrabalho | G19: Rollback parcial e correção dirigida | H19: Mitigar | I19: Ensaios de migração; validação amostral | J19: Plano de reversão na janela
A20: R13 | B20: Comunicação | C20: Comunicação | D20: Falhas de alinhamento entre times | E20: Decisões conflitantes e retrabalho | F20: Atrasos e perda de foco | G20: Ritual extraordinário de alinhamento | H20: Mitigar | I20: Cadência de governança, RACI | J20: Comitê de crise semanal
A21: R14 | B21: Conectividade | C21: Disponibilidade | D21: Dependência de link, ISP único | E21: Indisponibilidade do ambiente | F21: Parada de operação e SLA | G21: Redirecionar tráfego para link backup | H21: Transferir | I21: Redundância multi-ISP, health checks | J21: Failover automático e comunicação
A22: R15 | B22: Dev | C22: Vulnerabilidade | D22: Dependências desatualizadas | E22: Exploração de vulnerabilidades | F22: Incidente de segurança e parada | G22: Patch management emergencial | H22: Mitigar | I22: SCA/SAST, política de atualização | J22: Isolamento do serviço afetado

Sheet Qualificar
A1: Qualificação dos Riscos | AF1: Probabilidade | AI1: Impacto
K2: Base Custo | M2: 10000 | N2: R$
K3: Base Prazo | M3: 30 | N3: dias úteis
A4: =Identificar!A4 -> [sigla do projeto] - Nome do Projeto
AF5: Muito Baixa - 1 | AG5: 1 | AI5: Muito Baixo - 1 | AJ5: 1
A6: ID | B6: Declaração do Risco | E6: Resp. | F6: Probabilidade do risco virar incidente (Y) | G6: Avaliação de Impacto (X) | K6: Severidade (Y,X) | M6: Custo | N6: Prazo | AF6: Baixa - 2 | AG6: 2 | AI6: Muito Baixo - 2 | AJ6: 2
B7: CAUSA (Começa a frase com "Como Resultado ...") | C7: RISCO (Começar a frase com "Pode ocorrer ...") | D7: CONSEQÜÊNCIA (Começar a frase com "O que acarretaria ...") | G7: Aumento no Custo (X1) | H7: Desvio no Cronograma (X2) | I7: (X1*X2) | J7: Resultado do Impacto (X1+X2) | L7: Riscos Colaterais | AF7: Moderada - 3 | AG7: 3 | AI7: Baixo - 3 | AJ7: 3
A8: =IF(Identificar!A8<>"",Identificar!A8,"") -> R01 | B8: =IF(Identificar!D8<>"",Identificar!D8,"") -> Contratação tardia de equipe técnica | C8: =IF(Identificar!E8<>"",Identificar!E8,"") -> Atraso no início do desenvolvimento | D8: =IF(Identificar!F8<>"",Identificar!F8,"") -> Deslizamento de marcos e compressão do cronograma | E8: =IF(Identificar!G8<>"",Identificar!G8,"") -> Replanejar marcos e realocar atividades não críticas | F8: Alta - 0,4 | G8: Menor que 5% - 1,10 | H8: Entre 10% e 20% - 2,40 | I8: =IF(G8<>"",IF(H8<>"",RIGHT(G8,4)*RIGHT(H8,4),""),"") -> 2.64 | J8: =IF(I8<>"",VLOOKUP(I8,'[4]Sensibilidade ao Risco'!$E$2:$F$30,2,FALSE),"") -> Alta - 0,40 | K8: =IF(F8<>"",IF(J8<>"",(RIGHT(J8,3))*(RIGHT(F8,3)),""),"") -> 0.16 | L8: Atraso no projeto e aumento nos custos | M8: =ROUNDUP('Quantificar '!G8/Qualificar!$M$2,2) -> 1.2 | N8: =ROUNDUP('Quantificar '!H8/Qualificar!$M$3,2) -> 0.67 | AF8: Alta - 4 | AG8: 4 | AI8: Baixo - 4 | AJ8: 4
A9: =IF(Identificar!A9<>"",Identificar!A9,"") -> R02 | B9: =IF(Identificar!D9<>"",Identificar!D9,"") -> Reajustes contratuais e variação cambial | C9: =IF(Identificar!E9<>"",Identificar!E9,"") -> Estouro de orçamento | D9: =IF(Identificar!F9<>"",Identificar!F9,"") -> Redução de escopo e contingenciamento | E9: =IF(Identificar!G9<>"",Identificar!G9,"") -> Repriorizar entregas, acionar reserva gerencial | F9: Moderada - 0,2 | G9: Entre 5% e 10% - 1,20 | H9: Entre 10% e 20% - 2,40 | I9: =IF(G9<>"",IF(H9<>"",RIGHT(G9,4)*RIGHT(H9,4),""),"") -> 2.88 | J9: =IF(I9<>"",VLOOKUP(I9,'[4]Sensibilidade ao Risco'!$E$2:$F$30,2,FALSE),"") -> Alta - 0,40 | K9: =IF(F9<>"",IF(J9<>"",(RIGHT(J9,3))*(RIGHT(F9,3)),""),"") -> 0.08 | M9: =ROUNDUP('Quantificar '!G9/Qualificar!$M$2,2) -> 1 | N9: =ROUNDUP('Quantificar '!H9/Qualificar!$M$3,2) -> #VALUE!
A10: =IF(Identificar!A10<>"",Identificar!A10,"") -> R03 | B10: =IF(Identificar!D10<>"",Identificar!D10,"") -> Janela de testes comprimida | C10: =IF(Identificar!E10<>"",Identificar!E10,"") -> Defeitos críticos em produção | D10: =IF(Identificar!F10<>"",Identificar!F10,"") -> Retrabalho e custos adicionais | E10: =IF(Identificar!G10<>"",Identificar!G10,"") -> Gate Go/No-Go até sanar defeitos críticos | F10: Alta - 0,4 | G10: Menor que 5% - 1,10 | H10: Entre 5% e 10% - 2,20 | I10: =IF(G10<>"",IF(H10<>"",RIGHT(G10,4)*RIGHT(H10,4),""),"") -> 2.42 | J10: =IF(I10<>"",VLOOKUP(I10,'[4]Sensibilidade ao Risco'!$E$2:$F$30,2,FALSE),"") -> Moderada - 0,20 | K10: =IF(F10<>"",IF(J10<>"",(RIGHT(J10,3))*(RIGHT(F10,3)),""),"") -> 0.08 | M10: =ROUNDUP('Quantificar '!G10/Qualificar!$M$2,2) -> 1.1 | N10: =ROUNDUP('Quantificar '!H10/Qualificar!$M$3,2) -> 1
A11: =IF(Identificar!A11<>"",Identificar!A11,"") -> R04 | B11: =IF(Identificar!D11<>"",Identificar!D11,"") -> Ausências e rotatividade | C11: =IF(Identificar!E11<>"",Identificar!E11,"") -> Indisponibilidade de recursos-chave | D11: =IF(Identificar!F11<>"",Identificar!F11,"") -> Queda de produtividade e atrasos | E11: =IF(Identificar!G11<>"",Identificar!G11,"") -> Replanejar sprints e redistribuir tarefas | F11: Alta - 0,4 | G11: Menor que 5% - 1,10 | H11: Menor que 5% - 2,10 | I11: =IF(G11<>"",IF(H11<>"",RIGHT(G11,4)*RIGHT(H11,4),""),"") -> 2.31 | J11: =IF(I11<>"",VLOOKUP(I11,'[4]Sensibilidade ao Risco'!$E$2:$F$30,2,FALSE),"") -> Baixa - 0,10 | K11: =IF(F11<>"",IF(J11<>"",(RIGHT(J11,3))*(RIGHT(F11,3)),""),"") -> 0.04 | M11: =ROUNDUP('Quantificar '!G11/Qualificar!$M$2,2) -> 0.4 | N11: =ROUNDUP('Quantificar '!H11/Qualificar!$M$3,2) -> #VALUE!
A12: =IF(Identificar!A12<>"",Identificar!A12,"") -> R05 | B12: =IF(Identificar!D12<>"",Identificar!D12,"") -> SLA de terceiro apertado | C12: =IF(Identificar!E12<>"",Identificar!E12,"") -> Atraso em componentes de integração | D12: =IF(Identificar!F12<>"",Identificar!F12,"") -> Bloqueio de integrações e marcos | E12: =IF(Identificar!G12<>"",Identificar!G12,"") -> Paralelizar tarefas independentes | F12: Alta - 0,4 | G12: Insignificante - 1,05 | H12: Entre 10% e 20% - 2,40 | I12: =IF(G12<>"",IF(H12<>"",RIGHT(G12,4)*RIGHT(H12,4),""),"") -> 2.52 | J12: =IF(I12<>"",VLOOKUP(I12,'[4]Sensibilidade ao Risco'!$E$2:$F$30,2,FALSE),"") -> Moderada - 0,20 | K12: =IF(F12<>"",IF(J12<>"",(RIGHT(J12,3))*(RIGHT(F12,3)),""),"") -> 0.08 | M12: =ROUNDUP('Quantificar '!G12/Qualificar!$M$2,2) -> 1.2 | N12: =ROUNDUP('Quantificar '!H12/Qualificar!$M$3,2) -> #VALUE!
A13: =IF(Identificar!A13<>"",Identificar!A13,"") -> R06 | B13: =IF(Identificar!D13<>"",Identificar!D13,"") -> Novas demandas | C13: =IF(Identificar!E13<>"",Identificar!E13,"") -> Aumento de escopo | D13: =IF(Identificar!F13<>"",Identificar!F13,"") -> Pressão em prazo e custo | E13: =IF(Identificar!G13<>"",Identificar!G13,"") -> Acionar CCB e repriorizar backlog | F13: Muito Alta - 0,8 | G13: Entre 10% e 20% - 1,40 | H13: Maior que 20% - 2,80 | I13: =IF(G13<>"",IF(H13<>"",RIGHT(G13,4)*RIGHT(H13,4),""),"") -> 3.92 | J13: =IF(I13<>"",VLOOKUP(I13,'[4]Sensibilidade ao Risco'!$E$2:$F$30,2,FALSE),"") -> Muito Alta - 0,80 | K13: =IF(F13<>"",IF(J13<>"",(RIGHT(J13,3))*(RIGHT(F13,3)),""),"") -> 0.64 | M13: =ROUNDUP('Quantificar '!G13/Qualificar!$M$2,2) -> 1.8 | N13: =ROUNDUP('Quantificar '!H13/Qualificar!$M$3,2) -> #VALUE!
A14: =IF(Identificar!A14<>"",Identificar!A14,"") -> R07 | B14: =IF(Identificar!D14<>"",Identificar!D14,"") -> Interpretação tardia de requisitos | C14: =IF(Identificar!E14<>"",Identificar!E14,"") -> Não conformidade regulatória | D14: =IF(Identificar!F14<>"",Identificar!F14,"") -> Retrabalho e risco reputacional | E14: =IF(Identificar!G14<>"",Identificar!G14,"") -> Bloquear release até conformidade | F14: Moderada - 0,2 | G14: Insignificante - 1,05 | H14: Menor que 5% - 2,10 | I14: =IF(G14<>"",IF(H14<>"",RIGHT(G14,4)*RIGHT(H14,4),""),"") -> 2.205 | J14: =IF(I14<>"",VLOOKUP(I14,'[4]Sensibilidade ao Risco'!$E$2:$F$30,2,FALSE),"") -> Baixa - 0,10 | K14: =IF(F14<>"",IF(J14<>"",(RIGHT(J14,3))*(RIGHT(F14,3)),""),"") -> 0.02 | M14: =ROUNDUP('Quantificar '!G14/Qualificar!$M$2,2) -> 0.6 | N14: =ROUNDUP('Quantificar '!H14/Qualificar!$M$3,2) -> 0.34
A15: =IF(Identificar!A15<>"",Identificar!A15,"") -> R08 | B15: =IF(Identificar!D15<>"",Identificar!D15,"") -> Dados reais em testes; acessos excessivos | C15: =IF(Identificar!E15<>"",Identificar!E15,"") -> Vazamento de dados | D15: =IF(Identificar!F15<>"",Identificar!F15,"") -> Sanções e danos reputacionais | E15: =IF(Identificar!G15<>"",Identificar!G15,"") -> Acionar resposta a incidentes; notificar DPO | F15: Moderada - 0,2 | G15: Menor que 5% - 1,10 | H15: Entre 5% e 10% - 2,20 | I15: =IF(G15<>"",IF(H15<>"",RIGHT(G15,4)*RIGHT(H15,4),""),"") -> 2.42 | J15: =IF(I15<>"",VLOOKUP(I15,'[4]Sensibilidade ao Risco'!$E$2:$F$30,2,FALSE),"") -> Moderada - 0,20 | K15: =IF(F15<>"",IF(J15<>"",(RIGHT(J15,3))*(RIGHT(F15,3)),""),"") -> 0.04 | M15: =ROUNDUP('Quantificar '!G15/Qualificar!$M$2,2) -> 1.4 | N15: =ROUNDUP('Quantificar '!H15/Qualificar!$M$3,2) -> 0.5
A16: =IF(Identificar!A16<>"",Identificar!A16,"") -> R09 | B16: =IF(Identificar!D16<>"",Identificar!D16,"") -> Requisitos ambíguos | C16: =IF(Identificar!E16<>"",Identificar!E16,"") -> Entregas fora da necessidade do usuário | D16: =IF(Identificar!F16<>"",Identificar!F16,"") -> Retrabalho e baixa adoção | E16: =IF(Identificar!G16<>"",Identificar!G16,"") -> Refinamento com usuários e correções dirigidas | F16: Alta - 0,4 | G16: Insignificante - 1,05 | H16: Entre 5% e 10% - 2,20 | I16: =IF(G16<>"",IF(H16<>"",RIGHT(G16,4)*RIGHT(H16,4),""),"") -> 2.31 | J16: =IF(I16<>"",VLOOKUP(I16,'[4]Sensibilidade ao Risco'!$E$2:$F$30,2,FALSE),"") -> Baixa - 0,10 | K16: =IF(F16<>"",IF(J16<>"",(RIGHT(J16,3))*(RIGHT(F16,3)),""),"") -> 0.04 | M16: =ROUNDUP('Quantificar '!G16/Qualificar!$M$2,2) -> 0.5 | N16: =ROUNDUP('Quantificar '!H16/Qualificar!$M$3,2) -> 0.4
A17: =IF(Identificar!A17<>"",Identificar!A17,"") -> R10 | B17: =IF(Identificar!D17<>"",Identificar!D17,"") -> Capacidade insuficiente de ambiente | C17: =IF(Identificar!E17<>"",Identificar!E17,"") -> Degradação de performance | D17: =IF(Identificar!F17<>"",Identificar!F17,"") -> SLA violado e insatisfação | E17: =IF(Identificar!G17<>"",Identificar!G17,"") -> Escalar recursos; otimização | F17: Alta - 0,4 | G17: Menor que 5% - 1,10 | H17: Entre 5% e 10% - 2,20 | I17: =IF(G17<>"",IF(H17<>"",RIGHT(G17,4)*RIGHT(H17,4),""),"") -> 2.42 | J17: =IF(I17<>"",VLOOKUP(I17,'[4]Sensibilidade ao Risco'!$E$2:$F$30,2,FALSE),"") -> Moderada - 0,20 | K17: =IF(F17<>"",IF(J17<>"",(RIGHT(J17,3))*(RIGHT(F17,3)),""),"") -> 0.08 | M17: =ROUNDUP('Quantificar '!G17/Qualificar!$M$2,2) -> 0.9 | N17: =ROUNDUP('Quantificar '!H17/Qualificar!$M$3,2) -> 0.5
A18: =IF(Identificar!A18<>"",Identificar!A18,"") -> R11 | B18: =IF(Identificar!D18<>"",Identificar!D18,"") -> Capacitação insuficiente dos usuários | C18: =IF(Identificar!E18<>"",Identificar!E18,"") -> Baixa adoção do sistema | D18: =IF(Identificar!F18<>"",Identificar!F18,"") -> Queda de valor percebido | E18: =IF(Identificar!G18<>"",Identificar!G18,"") -> Capacitação extra pós-go-live | F18: Alta - 0,4 | G18: Entre 5% e 10% - 1,20 | H18: Entre 10% e 20% - 2,40 | I18: =IF(G18<>"",IF(H18<>"",RIGHT(G18,4)*RIGHT(H18,4),""),"") -> 2.88 | J18: =IF(I18<>"",VLOOKUP(I18,'[4]Sensibilidade ao Risco'!$E$2:$F$30,2,FALSE),"") -> Alta - 0,40 | K18: =IF(F18<>"",IF(J18<>"",(RIGHT(J18,3))*(RIGHT(F18,3)),""),"") -> 0.16 | M18: =ROUNDUP('Quantificar '!G18/Qualificar!$M$2,2) -> 0.3 | N18: =ROUNDUP('Quantificar '!H18/Qualificar!$M$3,2) -> 0.34
A19: =IF(Identificar!A19<>"",Identificar!A19,"") -> R12 | B19: =IF(Identificar!D19<>"",Identificar!D19,"") -> Inconsistências na migração | C19: =IF(Identificar!E19<>"",Identificar!E19,"") -> Erros operacionais pós-go-live | D19: =IF(Identificar!F19<>"",Identificar!F19,"") -> Interrupções e retrabalho | E19: =IF(Identificar!G19<>"",Identificar!G19,"") -> Rollback parcial e correção dirigida | F19: Alta - 0,4 | G19: Entre 5% e 10% - 1,20 | H19: Entre 10% e 20% - 2,40 | I19: =IF(G19<>"",IF(H19<>"",RIGHT(G19,4)*RIGHT(H19,4),""),"") -> 2.88 | J19: =IF(I19<>"",VLOOKUP(I19,'[4]Sensibilidade ao Risco'!$E$2:$F$30,2,FALSE),"") -> Alta - 0,40 | K19: =IF(F19<>"",IF(J19<>"",(RIGHT(J19,3))*(RIGHT(F19,3)),""),"") -> 0.16 | M19: =ROUNDUP('Quantificar '!G19/Qualificar!$M$2,2) -> 1.2 | N19: =ROUNDUP('Quantificar '!H19/Qualificar!$M$3,2) -> 0.67
A20: =IF(Identificar!A20<>"",Identificar!A20,"") -> R13 | B20: =IF(Identificar!D20<>"",Identificar!D20,"") -> Falhas de alinhamento entre times | C20: =IF(Identificar!E20<>"",Identificar!E20,"") -> Decisões conflitantes e retrabalho | D20: =IF(Identificar!F20<>"",Identificar!F20,"") -> Atrasos e perda de foco | E20: =IF(Identificar!G20<>"",Identificar!G20,"") -> Ritual extraordinário de alinhamento | F20: Alta - 0,4 | G20: Menor que 5% - 1,10 | H20: Entre 5% e 10% - 2,20 | I20: =IF(G20<>"",IF(H20<>"",RIGHT(G20,4)*RIGHT(H20,4),""),"") -> 2.42 | J20: =IF(I20<>"",VLOOKUP(I20,'[4]Sensibilidade ao Risco'!$E$2:$F$30,2,FALSE),"") -> Moderada - 0,20 | K20: =IF(F20<>"",IF(J20<>"",(RIGHT(J20,3))*(RIGHT(F20,3)),""),"") -> 0.08 | M20: =ROUNDUP('Quantificar '!G20/Qualificar!$M$2,2) -> 0.3 | N20: =ROUNDUP('Quantificar '!H20/Qualificar!$M$3,2) -> 0.34
... A22: =IF(Identificar!A22<>"",Identificar!A22,"") -> R15 | B22: =IF(Identificar!D22<>"",Identificar!D22,"") -> Dependências desatualizadas | C22: =IF(Identificar!E22<>"",Identificar!E22,"") -> Exploração de vulnerabilidades | D22: =IF(Identificar!F22<>"",Identificar!F22,"") -> Incidente de segurança e parada | E22: =IF(Identificar!G22<>"",Identificar!G22,"") -> Patch management emergencial | F22: Alta - 0,4 | G22: Entre 5% e 10% - 1,20 | H22: Entre 5% e 10% - 2,20 | I22: =IF(G22<>"",IF(H22<>"",RIGHT(G22,4)*RIGHT(H22,4),""),"") -> 2.64 | J22: =IF(I22<>"",VLOOKUP(I22,'[4]Sensibilidade ao Risco'!$E$2:$F$30,2,FALSE),"") -> Alta - 0,40 | K22: =IF(F22<>"",IF(J22<>"",(RIGHT(J22,3))*(RIGHT(F22,3)),""),"") -> 0.16 | M22: =ROUNDUP('Quantificar '!G22/Qualificar!$M$2,2) -> 0.9 | N22: =ROUNDUP('Quantificar '!H22/Qualificar!$M$3,2) -> 0.5
A23: =IF(Identificar!A23<>"",Identificar!A23,"") | B23: =IF(Identificar!D23<>"",Identificar!D23,"") | C23: =IF(Identificar!E23<>"",Identificar!E23,"") | D23: =IF(Identificar!F23<>"",Identificar!F23,"") | E23: =IF(Identificar!G23<>"",Identificar!G23,"") | I23: =IF(G23<>"",IF(H23<>"",RIGHT(G23,4)*RIGHT(H23,4),""),"") | J23: =IF(I23<>"",VLOOKUP(I23,'[4]Sensibilidade ao Risco'!$E$2:$F$30,2,FALSE),"") | K23: =IF(F23<>"",IF(J23<>"",(RIGHT(J23,3))*(RIGHT(F23,3)),""),"") | M23: =ROUNDUP('Quantificar '!G23/Qualificar!$M$2,2) -> 0 | N23: =ROUNDUP('Quantificar '!H23/Qualificar!$M$3,2) -> 0
A24: =IF(Identificar!A24<>"",Identificar!A24,"") | B24: =IF(Identificar!D24<>"",Identificar!D24,"") | C24: =IF(Identificar!E24<>"",Identificar!E24,"") | D24: =IF(Identificar!F24<>"",Identificar!F24,"") | E24: =IF(Identificar!G24<>"",Identificar!G24,"") | I24: =IF(G24<>"",IF(H24<>"",RIGHT(G24,4)*RIGHT(H24,4),""),"") | J24: =IF(I24<>"",VLOOKUP(I24,'[4]Sensibilidade ao Risco'!$E$2:$F$30,2,FALSE),"") | K24: =IF(F24<>"",IF(J24<>"",(RIGHT(J24,3))*(RIGHT(F24,3)),""),"") | M24: =ROUNDUP('Quantificar '!G24/Qualificar!$M$2,2) -> 0 | N24: =ROUNDUP('Quantificar '!H24/Qualificar!$M$3,2) -> 0
A25: =IF(Identificar!A25<>"",Identificar!A25,"") | B25: =IF(Identificar!D25<>"",Identificar!D25,"") | C25: =IF(Identificar!E25<>"",Identificar!E25,"") | D25: =IF(Identificar!F25<>"",Identificar!F25,"") | E25: =IF(Identificar!G25<>"",Identificar!G25,"") | I25: =IF(G25<>"",IF(H25<>"",RIGHT(G25,4)*RIGHT(H25,4),""),"") | J25: =IF(I25<>"",VLOOKUP(I25,'[4]Sensibilidade ao Risco'!$E$2:$F$30,2,FALSE),"") | K25: =IF(F25<>"",IF(J25<>"",(RIGHT(J25,3))*(RIGHT(F25,3)),""),"") | M25: =ROUNDUP('Quantificar '!G25/Qualificar!$M$2,2) -> 0 | N25: =ROUNDUP('Quantificar '!H25/Qualificar!$M$3,2) -> 0
A26: =IF(Identificar!A26<>"",Identificar!A26,"") | B26: =IF(Identificar!D26<>"",Identificar!D26,"") | C26: =IF(Identificar!E26<>"",Identificar!E26,"") | D26: =IF(Identificar!F26<>"",Identificar!F26,"") | E26: =IF(Identificar!G26<>"",Identificar!G26,"") | I26: =IF(G26<>"",IF(H26<>"",RIGHT(G26,4)*RIGHT(H26,4),""),"") | J26: =IF(I26<>"",VLOOKUP(I26,'[4]Sensibilidade ao Risco'!$E$2:$F$30,2,FALSE),"") | K26: =IF(F26<>"",IF(J26<>"",(RIGHT(J26,3))*(RIGHT(F26,3)),""),"") | M26: =ROUNDUP('Quantificar '!G26/Qualificar!$M$2,2) -> 0 | N26: =ROUNDUP('Quantificar '!H26/Qualificar!$M$3,2) -> 0
A27: =IF(Identificar!A27<>"",Identificar!A27,"") | B27: =IF(Identificar!D27<>"",Identificar!D27,"") | C27: =IF(Identificar!E27<>"",Identificar!E27,"") | D27: =IF(Identificar!F27<>"",Identificar!F27,"") | E27: =IF(Identificar!G27<>"",Identificar!G27,"") | I27: =IF(G27<>"",IF(H27<>"",RIGHT(G27,4)*RIGHT(H27,4),""),"") | J27: =IF(I27<>"",VLOOKUP(I27,'[4]Sensibilidade ao Risco'!$E$2:$F$30,2,FALSE),"") | K27: =IF(F27<>"",IF(J27<>"",(RIGHT(J27,3))*(RIGHT(F27,3)),""),"") | M27: =ROUNDUP('Quantificar '!G27/Qualificar!$M$2,2) -> 0 | N27: =ROUNDUP('Quantificar '!H27/Qualificar!$M$3,2) -> 0
F48: Insignificante - 1,05 | G48: Insignificante - 2,05 | H48: Muito baixa - 0,05
F49: Menor que 5% - 1,10 | G49: Menor que 5% - 2,10 | H49: Baixa - 0,1
F50: Entre 5% e 10% - 1,20 | G50: Entre 5% e 10% - 2,20 | H50: Moderada - 0,2
F51: Entre 10% e 20% - 1,40 | G51: Entre 10% e 20% - 2,40 | H51: Alta - 0,4
F52: Maior que 20% - 1,80 | G52: Maior que 20% - 2,80 | H52: Muito Alta - 0,8

Sheet Quantificar 
A1: Quantificação dos Riscos | AB1: Probabilidade | AE1: Impacto
A4: =Identificar!A4 -> [sigla do projeto] - Nome do Projeto
AB5: Muito Baixa - 1 | AC5: 1 | AE5: Muito Baixo - 1 | AF5: 1
A6: ID | B6: Declaração do Risco | E6: Resp. | G6: Impacto no Custo (Considerar qtde. de horas como unidade de medida, inclusive, a maior ou menor) | H6: Impacto no Cronograma (Colocar qtde. de dias de redução ou atraso no cronograma) | I6: Observação | J6: Plano de Prevenção | K6: Plano de Contingência | AB6: Baixa - 2 | AC6: 2 | AE6: Muito Baixo - 2 | AF6: 2
B7: CAUSA (Começa a frase com "Como Resultado ...") | C7: RISCO (Começar a frase com "Pode ocorrer ...") | D7: CONSEQÜÊNCIA (Começar a frase com "O que acarretaria ...") | F7: Riscos Colaterais | AB7: Moderada - 3 | AC7: 3 | AE7: Baixo - 3 | AF7: 3
